Workbook

Sheet Conciliacion_Transferencias
A1: Fecha | B1: Folio | C1: Cliente | D1: Servicio (s) | E1: Banco | F1: Monto | G1: ✅ Conciliado | H1: 💳 Concepto Banco | I1: 🔍 Observaciones
A2: 45977.042 | B2: 0-18592 | C2: Adan Mora | D2: Aveo | F2: 900 | G2: TRUE | H2: SPEI RECIBIDOMercado Pago/0139657603 722 4655821MERCADO*PAGO | I2: En esta falto $1
A3: 45977.042 | B3: 0-18743 | C3: Jorge | D3: sala + 4 sillas | F3: 1200 | G3: TRUE | H3: SPEI RECIBIDOBANAMEX/0139909434 002 0161125Lavado Jorge Herrera
A4: 45977.042 | B4: 0-18440 | C4: Georgina Crespo | D4: Sala L 5 plazas + 8 sillas + cabecera + box | F4: 1750 | G4: TRUE | H4: SPEI RECIBIDOSANTANDER/0140050765 014 9755000TRANSFERENCIA A LAVASMART SA D
A5: 45977.042 | B5: 0-18241 | C5: Laura Romero | D5: sala 3 y 2 px+ sofa cama+ colchon+ 6 sillas | E5: BANCOMER | F5: 2200 | G5: TRUE | H5: PAGO CUENTA DE TERCERO/ 0017746057 BNET 1584201510 laura Romero
A6: 45977.042 | B6: 0-18157 | C6: Sandra Diego | D6: colchón matrimonial | E6: SANTANDER | F6: 1200 | G6: TRUE | H6: SPEI RECIBIDOSANTANDER/0139758170 014 1543571TRANSFERENCIA A SANDRA DIEGO F
A7: 45978.042 | B7: 0-18163 | C7: Javier Hernandez | D7: Sala Grande + 4 sillas | E7: BANCOMER | F7: 1200 | G7: TRUE | H7: PAGO CUENTA DE TERCERO/ 0050780773 BNET 2912115158 javier hernandez
A8: 45978.042 | B8: 0-18375 | C8: Karen | D8: Sala 3 piezas + colchón + cabecera | E8: BANCOMER | F8: 1800 | G8: TRUE | H8: PAGO CUENTA DE TERCERO/ 0023488351 BNET 1582232138 serv 17 noviembre
A9: 45978.042 | B9: 0-18443 | C9: Abril | D9: 8 Sala para 5 personas + 4 sillas de comedor | E9: SPIN-AZUL | F9: 1000 | G9: TRUE | H9: SPEI RECIBIDOSPIN BY OXXO/0144784269 728 1414656lava
A10: 45978.042 | B10: 0-18595 | C10: Dany Soria | D10: carro chico | E10: BANAMEX | F10: 900 | G10: TRUE | H10: SPEI RECIBIDOBANAMEX/0144712916 002 0171125servicio auto | I10: Faltaba $1 pero si se transfirio
A11: 45978.042 | B11: 0-18746 | C11: Roberto Monzon | D11: Sala 2 piezas + 8 sillas de comedor + Colchón + Cabecera | E11: BANCOMER | F11: 2200 | G11: TRUE | H11: PAGO CUENTA DE TERCERO/ 0043033594 BNET 1217083084 limpieza casa 7 be
A12: 45978.042 | B12: 0-18747 | C12: Elizabeth Godínez | D12: Sala en L para 4 personas + 4 sillas de comedor | E12: SPEI | F12: 1200 | G12: TRUE | H12: SPEI RECIBIDOHSBC/0146144398 021 0171125Transferencia SPEI
A13: 45978.042 | B13: 0-18371 | C13: Karen díazDíaz | D13: Colchón king | E13: BANCOMER | F13: 750 | G13: TRUE | H13: SPEI RECIBIDOBANAMEX/0146461258 002 0171125mario ricci | I13: Hay sobrante de $100 (propina)
A14: 45979.042 | B14: 0-18164 | C14: Iris Gomez | D14: colchón Matrimonial | E14: BANORTE | F14: 750 | G14: TRUE | H14: SPEI RECIBIDOBANORTE/0149392901 072 0251118Clara Iris Gomez Marquez
A15: 45979.042 | B15: 0-18005 | C15: Adriana Gutierrez | D15: Sala L + 4 sillas +banca + colchon | E15: BANCOMER | F15: 1500 | G15: TRUE | H15: PAGO CUENTA DE TERCERO/ 0075425808 BNET 2911252356 Transf a LAVASMART
A16: 45979.042 | B16: 0-18250 | C16: Alejandra ALberchet | D16: sala L + tapete | E16: SPEI | F16: 1500 | G16: TRUE | H16: SPEI RECIBIDOSANTANDER/0152127870 014 8744960TRANSFERENCIA A LAVARSMART SA
A17: 45979.042 | B17: 0-18447 | C17: Myriam Luna | D17: Sala 4 piezas + fiat argo | E17: SPEI | F17: 1800 | G17: TRUE | H17: SPEI RECIBIDOBANAMEX/0150280265 002 0181125MYRIAM LUNA GTZ | I17: En esta falto $1
A18: 45979.042 | B18: 0-18748 | C18: Estela Flores | D18: sala + tapete | E18: BANCOMER | F18: 1350 | G18: TRUE | H18: PAGO CUENTA DE TERCERO/ 0018964785 BNET 1166057640 Servicio E Monjara | I18: En esta falto $1
A19: 45979.042 | B19: 0-18749 | C19: Jorge Gomez | D19: Oso de Peluche | E19: SANTANDER | F19: 600 | G19: TRUE | H19: SPEI RECIBIDOSANTANDER/0150170274 014 0000001TRANSFERENCIA A LAVASMART SA D
A20: 45979.042 | B20: 0-18598 | C20: Omar Martinez | D20: Sala 2 piezas + 8 sillas | E20: BANORTE | F20: 1450 | G20: TRUE | H20: SPEI RECIBIDOBANORTE/0149230521 072 0251118Sin informaci n
A21: 45979.042 | B21: 0-18600 | C21: Vianey oceguera | D21: 2 tapetes 156x225 +120x170 recoleccion | E21: BANCOMER | F21: 1200 | G21: TRUE | H21: PAGO CUENTA DE TERCERO/ 0065959922 BNET 0489023771 lavado alfombra
A22: 45979.042 | B22: 0-18601 | C22: Lourdes García | D22: 2 colchones + 2 sillones individuales | E22: BANAMEX | F22: 1400 | G22: TRUE | H22: SPEI RECIBIDOBANAMEX/0151912234 002 0181125pago lavado
A23: 45980.042 | B23: 0-18007 | C23: Juana | D23: Sala 2 piezas | E23: BANCOMER | F23: 600 | G23: TRUE | H23: PAGO CUENTA DE TERCERO/ 0077535859 BNET 2845125537 Lavado de sala
A24: 45980.042 | B24: 0-18603 | C24: María Nieto | D24: Sala L 3 plazas + sillón individual + 8 sillas (solo asiento) +tapete | E24: BANCOMER | F24: 1800 | G24: TRUE | H24: PAGO CUENTA DE TERCERO/ 0090827189 BNET 1548467788 Maria Nieto juriqu
A25: 45980.042 | B25: 0-18752 | C25: Emma Barrera | D25: Sala en forma de L +8 Cojines | E25: BANCOMER | F25: 1300 | G25: TRUE | H25: PAGO CUENTA DE TERCERO/ 0023450981 BNET 1506954415 Emma Barrera Maque | I25: Esta mal la fecha. Se realizo el servicio el 11/11/2025
A26: 45981.042 | B26: 0-18388 | C26: Marcos | D26: tapete chico | E26: SPEI | F26: 600 | G26: TRUE | H26: SPEI RECIBIDOSTP/0162342274 646 1116837Gto
A27: 45981.042 | B27: 0-18755 | C27: Mario Díaz | D27: Sala en L + 6 sillas + Colchón kin | E27: BANORTE | F27: 1900 | G27: TRUE | H27: SPEI RECIBIDOBANORTE/0161402003 072 0251120lavado colchon
A28: 45982.042 | B28: 0-18758 | C28: Jessica Escamilla | D28: Sala L con cojines | E28: SCOTIABANK | F28: 950 | G28: TRUE | H28: SPEI RECIBIDOSCOTIABANK/0166954586 044 0211125Transferencia a Lavasmart
A29: 45982.042 | B29: 0-18759 | C29: Cesar | D29: 2 sala L + 6 sillas | E29: BANCOMER | F29: 2300 | G29: TRUE | H29: PAGO CUENTA DE TERCERO/ 0034720809 BNET 2713152588 Transf a LAVASMART
A30: 45982.042 | B30: 0-18607 | C30: Ing Gamez | D30: mecedora + 5 sillas | E30: BANORTE | F30: 1400 | G30: TRUE | H30: SPEI RECIBIDOBANORTE/0166858620 072 0251121limpieza de tapetes y sillas
A31: 45982.042 | B31: 0-18609 | C31: Raul Carranza | D31: sala + 6 sillas | E31: SANTANDER | F31: 1250 | G31: TRUE | H31: SPEI RECIBIDOSANTANDER/0167870157 014 2522445TRANSFERENCIA A LAVA SMART
A32: 45982.042 | B32: 0-18610 | C32: José Sanchez | D32: toledo | E32: NU-MORADO | F32: 900 | G32: TRUE | H32: PAGO CUENTA DE TERCERO/ 0062778768 BNET 1542236049 pago servicio
A33: 45982.042 | B33: 0-18013 | C33: Jonathan Martinez | D33: carro chico | F33: 900 | G33: FALSE | H33: PAGO CUENTA DE TERCERO/ 0054216233 BNET 0485580439 Transf a LAVASMART | I33: Borrar
A34: 45982.042 | B34: 0-18014 | C34: Pamela Pintado | D34: Carreola + silla de bebe | F34: 850 | G34: FALSE | I34: Borrar
A35: 45982.042 | B35: 0-18015 | C35: Angel Gonzalez | D35: 3 colchones | F35: 1500 | G35: FALSE | I35: Borrar
A36: 45982.042 | B36: 0-18016 | C36: José Maria Machuca | D36: tapete chico | E36: SANTANDER | F36: 700 | G36: TRUE | H36: SPEI RECIBIDOSANTANDER/0169198782 014 0821954SONIA PEREZ LAVADO DE TAPETE
A37: 45982.042 | B37: 0-18389 | C37: Brenda Vera | D37: Kia Sportage Asientos de Tela | F37: 850 | G37: FALSE | I37: Borrar
A38: 45982.042 | B38: 0-18390 | C38: Eugenia Altamirano | D38: colchón king + mecedora | F38: 1000 | G38: FALSE | I38: Borrar
A39: 45982.042 | B39: 0-18391 | C39: Marycarmen Vazquez | D39: Sala 2 pz + 2 sillones indivuales + 8 sillas + tapete 2x2 | F39: 2500 | G39: FALSE | I39: Borrar
A40: 45982.042 | B40: 0-18261 | C40: Álvaro González | D40: Kia Rio | F40: 850 | G40: FALSE | I40: Borrar
...

Sheet Banco
A1: Día | B1: Concepto / Referencia | C1: cargo | D1: Abono | E1: Saldo | F1: Folio
A2: 45966 | B2: SPEI RECIBIDOHSBC/0177980786 021 0051125Arturo de Cardenas | D2: 900 | E2: 64403.53
A3: 45966 | B3: PAGO CUENTA DE TERCERO/ 0036729331 BNET 2723378160 tapetes | D3: 1000 | E3: 63503.53
A4: 45966 | B4: PAGO CUENTA DE TERCERO/ 0039336585 BNET 2960808008 lavasnart | D4: 1000 | E4: 62503.53
A5: 45966 | B5: SPEI RECIBIDOSANTANDER/0175746190 014 3422688ALEJANDRO DOMINGUEZ | D5: 850 | E5: 61503.53
A6: 45966 | B6: DEPOSITO EN EFECTIVO/0015175 | D6: 10850 | E6: 60653.53
A7: 45966 | B7: TRASPASO CUENTAS PROPIAS/ 1324865757 CUENTA: 0120217220 BNET | C7: 70000 | E7: 49803.53
A8: 45966 | B8: TRASPASO CUENTAS PROPIAS/ 1324814778 CUENTA: 0125721601 BNET | D8: 50032.82 | E8: 119803.53
A9: 45966 | B9: PAGO CUENTA DE TERCERO/ 0050922952 BNET 1599726333 Ricardo Benitez | D9: 701 | E9: 69770.71
A10: 45966 | B10: IVA COM. VENTAS CREDITO/174771412 TERMINALES PUNTO DE VENTA | C10: 4.32 | E10: 69069.71
A11: 45966 | B11: COMISION VENTAS CREDITO/174771412 TERMINALES PUNTO DE VENTA | C11: 26.97 | E11: 69074.03
A12: 45966 | B12: VENTAS CREDITO/144771412 TERMINALES PUNTO DE VENTA | D12: 1199 | E12: 69101
A13: 45967 | B13: PAGO CUENTA DE TERCERO/ 0053933298 BNET 1536166349 Frida Ruiz PROPINA | D13: 100 | E13: 95616.92
A14: 45967 | B14: SPEI RECIBIDOMercado Pago/0183385533 722 1820119Limpieza sillón | D14: 1000 | E14: 95516.92
A15: 45967 | B15: PAGO CUENTA DE TERCERO/ 0047245315 BNET 1570646977 Transf a Lavasmart | D15: 1000 | E15: 94516.92
A16: 45967 | B16: PAGO CUENTA DE TERCERO/ 0020194086 BNET 1243083357 lavado sillones | D16: 1650 | E16: 93516.92
A17: 45967 | B17: SPEI RECIBIDOSCOTIABANK/0182304620 044 0000001pago por lavado de sala | D17: 750 | E17: 91866.92
A18: 45967 | B18: PAGO CUENTA DE TERCERO/ 0084590834 BNET 2752418789 lago pom261 | D18: 950 | E18: 91116.92
A19: 45967 | B19: DEPOSITO EFECTIVO PRACTIC/******5546 NOV06 12:21 PRAC 7490 FOLIO:1123 | D19: 10900 | E19: 90166.92 | F19: 0-18743
A20: 45967 | B20: SPEI RECIBIDOBANAMEX/0181875752 002 0061125Dos alfombras | D20: 1450 | E20: 79266.92
A21: 45967 | B21: PAGO CUENTA DE TERCERO/ 0090425130 BNET 0469938362 Yo | D21: 1000 | E21: 77816.92
A22: 45967 | B22: PAGO CUENTA DE TERCERO/ 0072858732 BNET 0446170188 tapetes | D22: 1200 | E22: 76816.92
A23: 45967 | B23: PAGO CUENTA DE TERCERO/ 0081718014 BNET 0125305241 pago | D23: 3950 | E23: 75616.92
A24: 45967 | B24: SPEI RECIBIDOBANORTE/0180649497 072 0251106Sin informaci n | D24: 300 | E24: 71666.92
A25: 45967 | B25: IVA COM. VENTAS CREDITO/174771419 TERMINALES PUNTO DE VENTA | C25: 9.72 | E25: 71366.92
A26: 45967 | B26: COMISION VENTAS CREDITO/174771419 TERMINALES PUNTO DE VENTA | C26: 60.75 | E26: 71376.64
A27: 45967 | B27: VENTAS CREDITO/144771419 TERMINALES PUNTO DE VENTA | D27: 2700 | E27: 71437.39
A28: 45967 | B28: IVA COM. VENTAS CREDITO/174764991 TERMINALES PUNTO DE VENTA | C28: 8.64 | E28: 68737.39
A29: 45967 | B29: COMISION VENTAS CREDITO/174764991 TERMINALES PUNTO DE VENTA | C29: 54 | E29: 68746.03
A30: 45967 | B30: VENTAS CREDITO/144764991 TERMINALES PUNTO DE VENTA | D30: 2400 | E30: 68800.03
A31: 45967 | B31: IVA COM. VENTAS DEBITO/174895225 TERMINALES PUNTO DE VENTA | C31: 4.32 | E31: 66400.03
A32: 45967 | B32: COMISION VENTAS DEBITO/174895225 TERMINALES PUNTO DE VENTA | C32: 27 | E32: 66404.35
A33: 45967 | B33: VENTAS DEBITO/144895225 TERMINALES PUNTO DE VENTA | D33: 1200 | E33: 66431.35
A34: 45967 | B34: IVA COM. VENTAS CREDITO/174895225 TERMINALES PUNTO DE VENTA | C34: 3.06 | E34: 65231.35
A35: 45967 | B35: COMISION VENTAS CREDITO/174895225 TERMINALES PUNTO DE VENTA | C35: 19.12 | E35: 65234.41
A36: 45967 | B36: VENTAS CREDITO/144895225 TERMINALES PUNTO DE VENTA | D36: 850 | E36: 65253.53
A37: 45968 | B37: SPEI RECIBIDOBANCOPPEL/0188955951 137 9093087Transf. a lavasmart | D37: 1200 | E37: 128366.85
A38: 45968 | B38: SPEI RECIBIDOINBURSA/0188893024 036 2025110Mónica Franco | D38: 1200 | E38: 127166.85
A39: 45968 | B39: DEPOSITO EN EFECTIVO/0015230 | D39: 14295 | E39: 125966.85
A40: 45968 | B40: PAGO CUENTA DE TERCERO/ 0081156146 BNET 1549512538 servicio tapete | D40: 600 | E40: 111671.85
...

Sheet cat
K2: Tipos de incidencia
J3: 1 | K3: Falta evidencia (nota de venta) | L3: Pendiente
J4: 2 | K4: Nota de venta ilegible | L4: En progreso
J5: 3 | K5: Falta comprobante de pago | L5: Revisar nuevamente
J6: 4 | K6: Comprobante incorrecto | L6: Resuelto
J7: 5 | K7: Método de pago incorrecto
J8: 6 | K8: Discrepancia entre reporte y deposito
J9: 7 | K9: Falta de carga de evidencia
K11: Otro

Sheet Conciliacion_Tarjetas
A1: Fecha | B1: Folio | C1: Cliente | D1: Servicio (s) | E1: Monto | F1: 🧾 Recibo | G1: afiliación | H1: 📦 # Lote | I1: 🔍 Observaciones
A2: 45990.042 | B2: 0-18045 | C2: Graciela Mayorga | D2: Sala 2 Plazas | E2: 850 | F2: SI | G2: 4771419 | H2: 14
A3: 45990.042 | B3: 0-18046 | C3: Ramón Quijano | D3: sillon 3 plazas | E3: 1070 | F3: SI | G3: 4771419 | H3: 14
A4: 45990.042 | B4: 0-18896 | C4: Belem de La Fuente | D4: Colchón king + sillon reclinable | E4: 1400 | F4: SI | G4: 4764954 | H4: 190
A5: 45990.042 | B5: 0-18897 | C5: Marisela Aguilera | D5: sala en L para 8 personas + sofá cama | E5: 1800
A6: 45990.042 | B6: 0-18319 | C6: Guadalupe Hernandez | D6: 3 colchones | E6: 1500 | F6: SI | G6: 4895225 | H6: 15
A7: 45990.042 | B7: 0-17855 | C7: Bernardette Espin | D7: Auto Chico + sala 5 plazas + tapete 1.6 x 2.3 | E7: 1850 | F7: SI | G7: 4895225 | H7: 86
A8: 45991.042 | B8: 0-17857 | C8: Antonio Aranda | D8: Hyundai Onix | E8: 900 | F8: SI | G8: 4895225 | H8: 87
A9: 45991.042 | B9: 0-18323 | C9: Adrían León | D9: 2 tapetes + alfombra | E9: 2000
A10: 45990.042 | B10: 0-18635 | C10: Paz Flores | D10: Sala 3 piezas | E10: 850
A11: 45990.042 | B11: 0-18791 | C11: Adriana Guerrero | D11: sofá 3 plazas | E11: 750
A12: 45991.042 | B12: 0-18486 | C12: Antonio Prado | D12: sala 3 piezas | E12: 850
A13: 45991.042 | B13: 0-18488 | C13: Patricia Ojeda | D13: camioneta chica+ 6 sillas | E13: 1300
A14: 45991.042 | B14: 0-18639 | C14: Carlos Sánchez | D14: Auto chico | E14: 900
A15: 45991.042 | B15: 0-18640 | C15: Heriberto Rodríguez | D15: Sala L | E15: 950
A16: 45991.042 | B16: 0-18792 | C16: María Eugenia Anzuresz | D16: 4 sillas + 3 colchones (queen y king) + Sala de 3 piezas + tapete 1x1.80 | E16: 3200
A17: 45992.042 | B17: 0-17860 | C17: Rosa Campos | D17: Sala L + sillón 3 plazas | E17: 1250
A18: 45992.042 | B18: 0-17861 | C18: Elizabeth Lozada | D18: Sala 2 piezas + 2 tapetes 1.8x1.20 | E18: 1400
A19: 45992.042 | B19: 0-17862 | C19: Mónica Jiménez | D19: Vento | E19: 900
A20: 45992.042 | B20: 0-18299 | C20: Norma Rojas | D20: Sala L+ 5 cojines decorativos | E20: 850
... A41: 45994.042 | B41: 0-18499 | C41: Ana Camarena | D41: 6 tapetes de 2x1 y 4 sillas | E41: 3000

Sheet Cierres_Lotes

Sheet 📢 Bitácora_Hallazgos
A2: 📅 Fecha Reporte | B2: 🚨 Tipo de Hallazgo | C2: 📝 Folio | D2: ⚠️ Urgencia | E2: 💬 Descripción Detallada | F2: 🚧 Estado | G2: 💡 Resolución / Respuesta
A3: 45982 | B3: Discrepancia entre reporte y deposito | C3: 0-18051 | D3: 🔥 ALTA | E3: El pago no está en el banco | F3: Pendiente | H3: <- Ejemplo (borrar)
A4: 45980 | B4: Discrepancia entre reporte y deposito | C4: 0-18752 | D4: 🔥 ALTA | E4: Es un lavado de sala el costo es de $1300 y en el banco solo hay $950 | F4: Pendiente
A5: 45977 | B5: Falta comprobante de pago | C5: 0-18897 | D5: 🔥 ALTA | F5: Pendiente
A6: 45977 | B6: Falta comprobante de pago | C6: 0-18157 | D6: 🔥 ALTA | F6: Pendiente

Sheet totales
A1: Fecha | B1: Transferencia | C1: Banco
A2: 45658 | B2: =SUMIFS(Conciliacion_Transferencias!$F$2:$F1000,Conciliacion_Transferencias!$A$2:$A1000,$A2) -> 0
A3: 45659 | B3: =SUMIFS(Conciliacion_Transferencias!$F$2:$F1000,Conciliacion_Transferencias!$A$2:$A1000,$A3) -> 0
A4: 45660 | B4: =SUMIFS(Conciliacion_Transferencias!$F$2:$F1000,Conciliacion_Transferencias!$A$2:$A1000,$A4) -> 0
A5: 45661 | B5: =SUMIFS(Conciliacion_Transferencias!$F$2:$F1000,Conciliacion_Transferencias!$A$2:$A1000,$A5) -> 0
A6: 45662 | B6: =SUMIFS(Conciliacion_Transferencias!$F$2:$F1000,Conciliacion_Transferencias!$A$2:$A1000,$A6) -> 0
A7: 45663 | B7: =SUMIFS(Conciliacion_Transferencias!$F$2:$F1000,Conciliacion_Transferencias!$A$2:$A1000,$A7) -> 0
A8: 45664 | B8: =SUMIFS(Conciliacion_Transferencias!$F$2:$F1000,Conciliacion_Transferencias!$A$2:$A1000,$A8) -> 0
A9: 45665 | B9: =SUMIFS(Conciliacion_Transferencias!$F$2:$F1000,Conciliacion_Transferencias!$A$2:$A1000,$A9) -> 0
A10: 45666 | B10: =SUMIFS(Conciliacion_Transferencias!$F$2:$F1000,Conciliacion_Transferencias!$A$2:$A1000,$A10) -> 0
A11: 45667 | B11: =SUMIFS(Conciliacion_Transferencias!$F$2:$F1000,Conciliacion_Transferencias!$A$2:$A1000,$A11) -> 0
A12: 45668 | B12: =SUMIFS(Conciliacion_Transferencias!$F$2:$F1000,Conciliacion_Transferencias!$A$2:$A1000,$A12) -> 0
A13: 45669 | B13: =SUMIFS(Conciliacion_Transferencias!$F$2:$F1000,Conciliacion_Transferencias!$A$2:$A1000,$A13) -> 0
A14: 45670 | B14: =SUMIFS(Conciliacion_Transferencias!$F$2:$F1000,Conciliacion_Transferencias!$A$2:$A1000,$A14) -> 0
A15: 45671 | B15: =SUMIFS(Conciliacion_Transferencias!$F$2:$F1000,Conciliacion_Transferencias!$A$2:$A1000,$A15) -> 0
A16: 45672 | B16: =SUMIFS(Conciliacion_Transferencias!$F$2:$F1000,Conciliacion_Transferencias!$A$2:$A1000,$A16) -> 0
A17: 45673 | B17: =SUMIFS(Conciliacion_Transferencias!$F$2:$F1000,Conciliacion_Transferencias!$A$2:$A1000,$A17) -> 0
A18: 45674 | B18: =SUMIFS(Conciliacion_Transferencias!$F$2:$F1000,Conciliacion_Transferencias!$A$2:$A1000,$A18) -> 0
A19: 45675 | B19: =SUMIFS(Conciliacion_Transferencias!$F$2:$F1000,Conciliacion_Transferencias!$A$2:$A1000,$A19) -> 0
A20: 45676 | B20: =SUMIFS(Conciliacion_Transferencias!$F$2:$F1000,Conciliacion_Transferencias!$A$2:$A1000,$A20) -> 0
A21: 45677 | B21: =SUMIFS(Conciliacion_Transferencias!$F$2:$F1000,Conciliacion_Transferencias!$A$2:$A1000,$A21) -> 0
A22: 45678 | B22: =SUMIFS(Conciliacion_Transferencias!$F$2:$F1000,Conciliacion_Transferencias!$A$2:$A1000,$A22) -> 0
A23: 45679 | B23: =SUMIFS(Conciliacion_Transferencias!$F$2:$F1000,Conciliacion_Transferencias!$A$2:$A1000,$A23) -> 0
A24: 45680 | B24: =SUMIFS(Conciliacion_Transferencias!$F$2:$F1000,Conciliacion_Transferencias!$A$2:$A1000,$A24) -> 0
A25: 45681 | B25: =SUMIFS(Conciliacion_Transferencias!$F$2:$F1000,Conciliacion_Transferencias!$A$2:$A1000,$A25) -> 0
A26: 45682 | B26: =SUMIFS(Conciliacion_Transferencias!$F$2:$F1000,Conciliacion_Transferencias!$A$2:$A1000,$A26) -> 0
A27: 45683 | B27: =SUMIFS(Conciliacion_Transferencias!$F$2:$F1000,Conciliacion_Transferencias!$A$2:$A1000,$A27) -> 0
A28: 45684 | B28: =SUMIFS(Conciliacion_Transferencias!$F$2:$F1000,Conciliacion_Transferencias!$A$2:$A1000,$A28) -> 0
A29: 45685 | B29: =SUMIFS(Conciliacion_Transferencias!$F$2:$F1000,Conciliacion_Transferencias!$A$2:$A1000,$A29) -> 0
A30: 45686 | B30: =SUMIFS(Conciliacion_Transferencias!$F$2:$F1000,Conciliacion_Transferencias!$A$2:$A1000,$A30) -> 0
A31: 45687 | B31: =SUMIFS(Conciliacion_Transferencias!$F$2:$F1000,Conciliacion_Transferencias!$A$2:$A1000,$A31) -> 0
A32: 45688 | B32: =SUMIFS(Conciliacion_Transferencias!$F$2:$F1000,Conciliacion_Transferencias!$A$2:$A1000,$A32) -> 0
A33: 45689 | B33: =SUMIFS(Conciliacion_Transferencias!$F$2:$F1000,Conciliacion_Transferencias!$A$2:$A1000,$A33) -> 0
A34: 45690 | B34: =SUMIFS(Conciliacion_Transferencias!$F$2:$F1000,Conciliacion_Transferencias!$A$2:$A1000,$A34) -> 0
A35: 45691 | B35: =SUMIFS(Conciliacion_Transferencias!$F$2:$F1000,Conciliacion_Transferencias!$A$2:$A1000,$A35) -> 0
A36: 45692 | B36: =SUMIFS(Conciliacion_Transferencias!$F$2:$F1000,Conciliacion_Transferencias!$A$2:$A1000,$A36) -> 0
A37: 45693 | B37: =SUMIFS(Conciliacion_Transferencias!$F$2:$F1000,Conciliacion_Transferencias!$A$2:$A1000,$A37) -> 0
A38: 45694 | B38: =SUMIFS(Conciliacion_Transferencias!$F$2:$F1000,Conciliacion_Transferencias!$A$2:$A1000,$A38) -> 0
A39: 45695 | B39: =SUMIFS(Conciliacion_Transferencias!$F$2:$F1000,Conciliacion_Transferencias!$A$2:$A1000,$A39) -> 0
A40: 45696 | B40: =SUMIFS(Conciliacion_Transferencias!$F$2:$F1000,Conciliacion_Transferencias!$A$2:$A1000,$A40) -> 0
...

Sheet 📝 Bitácora_Cambios
A1: Timestamp | B1: Folio | C1: Campo Modificado | D1: Valor Anterior | E1: Valor Nuevo
A2: 45984.941 | B2: 0-18758 | C2: Banco: → SCOTIABANK | D2: Monto: 950; Banco: | E2: Monto: 950; Banco: SCOTIABANK
A3: 45984.941 | B3: 0-18759 | C3: Banco: → BANCOMER | D3: Monto: 2300; Banco: | E3: Monto: 2300; Banco: BANCOMER
A4: 45984.941 | B4: 0-18607 | C4: Banco: → BANORTE | D4: Monto: 1400; Banco: | E4: Monto: 1400; Banco: BANORTE
A5: 45984.941 | B5: 0-18609 | C5: Banco: → SANTANDER | D5: Monto: 1250; Banco: | E5: Monto: 1250; Banco: SANTANDER
A6: 45984.941 | B6: 0-18610 | C6: Banco: → NU-MORADO | D6: Monto: 900; Banco: | E6: Monto: 900; Banco: NU-MORADO
A7: 45984.941 | B7: 0-18016 | C7: Banco: → SANTANDER | D7: Monto: 700; Banco: | E7: Monto: 700; Banco: SANTANDER
A8: 45986.941 | B8: 0-18270 | C8: Monto: 2300 → 2400 | D8: Monto: 2300; Banco: | E8: Monto: 2400; Banco:
A9: 45987.941 | B9: 0-18270 | C9: Banco: → BANCOMER | D9: Monto: 2400; Banco: | E9: Monto: 2400; Banco: BANCOMER
A10: 45988.941 | B10: 0-18281 | C10: Banco: → SANTANDER | D10: Monto: 1200; Banco: | E10: Monto: 1200; Banco: SANTANDER
A11: 45988.941 | B11: 0-18283 | C11: Banco: → BANCOMER | D11: Monto: 850; Banco: | E11: Monto: 850; Banco: BANCOMER
A12: 45988.941 | B12: 0-18034 | C12: Banco: → BANCOMER | D12: Monto: 1200; Banco: | E12: Monto: 1200; Banco: BANCOMER
A13: 45988.941 | B13: 0-18196 | C13: Banco: → BANAMEX | D13: Monto: 750; Banco: | E13: Monto: 750; Banco: BANAMEX
... A41: 45994.941 | B41: 0-18801 | C41: Monto: 950 → 1450; Banco: SANTANDER → | D41: Monto: 950; Banco: SANTANDER | E41: Monto: 1450; Banco:
A42: 45995.503 | B42: 0-17899 | C42: ACTUALIZACIÓN | D42: Cambios en: Banco | E42: Banco: (vacío) | F42: Banco: BANAMEX
A43: 45995.503 | B43: 0-18652 | C43: ACTUALIZACIÓN | D43: Cambios en: Banco | E43: Banco: (vacío) | F43: Banco: BANORTE
A44: 45995.503 | B44: 0-18800 | C44: ACTUALIZACIÓN | D44: Cambios en: Banco | E44: Banco: (vacío) | F44: Banco: BANAMEX
A45: 45995.503 | B45: 0-18497 | C45: ACTUALIZACIÓN | D45: Cambios en: Banco | E45: Banco: (vacío) | F45: Banco: Mercado Pago- Amarillo
A46: 45995.503 | B46: 0-18498 | C46: ACTUALIZACIÓN | D46: Cambios en: Banco | E46: Banco: (vacío) | F46: Banco: BANBAJIO
A47: 45995.503 | B47: 0-17899 | C47: ACTUALIZACIÓN | D47: Cambios en: Banco | E47: Banco: (vacío) | F47: Banco: BANAMEX
A48: 45995.503 | B48: 0-18652 | C48: ACTUALIZACIÓN | D48: Cambios en: Banco | E48: Banco: (vacío) | F48: Banco: BANORTE
A49: 45995.503 | B49: 0-18800 | C49: ACTUALIZACIÓN | D49: Cambios en: Banco | E49: Banco: (vacío) | F49: Banco: BANAMEX
